<?xml version="1.0" encoding="UTF-8" ?>
<robot name="dofbot">

    <!-- Table Link -->
    <link name="table_link">
        <visual>
            <geometry>
                <box size="1.2 0.6 0.75"/>
            </geometry>
            <material name="grey">
                <color rgba="0.5 0.5 0.5 1"/>
            </material>
        </visual>
        <collision>
            <geometry>
                <box size="1.2 0.6 0.75"/>
            </geometry>
        </collision>
    </link>

    <!-- Table Joint (Fixed) -->
    <joint name="table_joint" type="fixed">
        <parent link="world"/>
        <child link="table_link"/>
        <origin xyz="0 0 0.375" rpy="0 0 0"/>
    </joint>

    <!-- Base Link (Now on Top of the Table) -->
    <link name="base_link">
        <visual>
            <origin xyz="0 0 0.75" rpy="0 0 0" /> <!-- Adjusted height to sit on the table -->
            <geometry>
                <mesh filename="package://dofbot_moveit/meshes/base_link.STL" />
            </geometry>
            <material name="">
                <color rgba="0.592 0.666 0.682 1" />
            </material>
        </visual>
        <collision>
            <origin xyz="0 0 0.75" rpy="0 0 0" />
            <geometry>
                <mesh filename="package://dofbot_moveit/meshes/base_link.STL" />
            </geometry>
        </collision>
    </link>

    <!-- Base Joint (Fixed to Table) -->
    <joint name="base_joint" type="fixed">
        <parent link="table_link"/>
        <child link="base_link"/>
        <origin xyz="0 0 0.75" rpy="0 0 0"/>
    </joint>

    <!-- Rest of the robot structure remains unchanged -->
    
    <joint name="joint1" type="revolute">
        <origin xyz="0 0 0.06605" rpy="-0.010805 0 0" />
        <parent link="base_link" />
        <child link="link1" />
        <axis xyz="0 0 1" />
        <limit effort="30" velocity="1.0" lower="-1.5708" upper="1.5708"/>
    </joint>

    <!-- Other joints and links remain unchanged -->

    <!-- Camera Link (On Top of the Robot) -->
    <link name="camera_link">
        <visual>
            <origin xyz="0 0 0.15" rpy="0 0 0"/> <!-- Positioned above link5 -->
            <geometry>
                <box size="0.05 0.05 0.05"/>
            </geometry>
            <material name="black">
                <color rgba="0 0 0 1"/>
            </material>
        </visual>
    </link>

    <!-- Camera Joint -->
    <joint name="camera_joint" type="fixed">
        <parent link="link5"/>
        <child link="camera_link"/>
        <origin xyz="0 0 0.15" rpy="0 0 0"/>
    </joint>

    <!-- Camera Sensor -->
    <gazebo>
        <sensor type="camera" name="camera_sensor">
            <update_rate>30</update_rate>
            <camera>
                <horizontal_fov>1.047</horizontal_fov>
                <image>
                    <width>640</width>
                    <height>480</height>
                    <format>R8G8B8</format>
                </image>
            </camera>
            <plugin name="camera_controller" filename="libgazebo_ros_camera.so">
                <cameraName>camera</cameraName>
                <imageTopicName>image_raw</imageTopicName>
                <cameraInfoTopicName>camera_info</cameraInfoTopicName>
                <frameName>camera_link</frameName>
            </plugin>
        </sensor>
    </gazebo>
</robot>
