<?xml version="1.0" ?>
<robot name="human_sitting">
  
  <!-- Torso -->
  <link name="torso">
    <visual>
      <geometry>
        <cylinder radius="0.15" length="0.5"/>
      </geometry>
      <material name="Skin">
        <color rgba="0.9 0.7 0.6 1"/>
      </material>
    </visual>
  </link>

  <!-- Head -->
  <link name="head">
    <visual>
      <geometry>
        <sphere radius="0.12"/>
      </geometry>
      <material name="Skin">
        <color rgba="0.9 0.7 0.6 1"/>
      </material>
    </visual>
  </link>

  <!-- Arms -->
  <link name="upper_arm_left">
    <visual>
      <geometry>
        <cylinder radius="0.06" length="0.3"/>
      </geometry>
      <material name="Skin"/>
    </visual>
  </link>

  <link name="upper_arm_right">
    <visual>
      <geometry>
        <cylinder radius="0.06" length="0.3"/>
      </geometry>
      <material name="Skin"/>
    </visual>
  </link>

  <!-- Thighs -->
  <link name="thigh_left">
    <visual>
      <geometry>
        <cylinder radius="0.08" length="0.4"/>
      </geometry>
      <material name="Blue">
        <color rgba="0.0 0.0 1.0 1"/>
      </material>
    </visual>
  </link>

  <link name="thigh_right">
    <visual>
      <geometry>
        <cylinder radius="0.08" length="0.4"/>
      </geometry>
      <material name="Blue"/>
    </visual>
  </link>

  <!-- Lower Legs -->
  <link name="lower_leg_left">
    <visual>
      <geometry>
        <cylinder radius="0.07" length="0.4"/>
      </geometry>
      <material name="Green"/>
    </visual>
  </link>

  <link name="lower_leg_right">
    <visual>
      <geometry>
        <cylinder radius="0.07" length="0.4"/>
      </geometry>
      <material name="Green"/>
    </visual>
  </link>

  <!-- Joints -->
  <joint name="torso_to_head" type="fixed">
    <parent link="torso"/>
    <child link="head"/>
    <origin xyz="0 0 0.3" rpy="0 0 0"/>
  </joint>

  <joint name="torso_to_thigh_left" type="revolute">
    <parent link="torso"/>
    <child link="thigh_left"/>
    <origin xyz="-0.1 0 -0.3" rpy="0 0 0"/>
    <axis xyz="0 1 0"/>
    <limit lower="-1.57" upper="1.57" effort="100.0" velocity="1.0"/>
  </joint>

  <joint name="torso_to_thigh_right" type="revolute">
    <parent link="torso"/>
    <child link="thigh_right"/>
    <origin xyz="0.1 0 -0.3" rpy="0 0 0"/>
    <axis xyz="0 1 0"/>
    <limit lower="-1.57" upper="1.57" effort="100.0" velocity="1.0"/>
  </joint>

  <joint name="thigh_left_to_lower_leg_left" type="revolute">
    <parent link="thigh_left"/>
    <child link="lower_leg_left"/>
    <origin xyz="0 -0.2 0" rpy="0 0 0"/>
    <axis xyz="0 1 0"/>
    <limit lower="-1.57" upper="0" effort="100.0" velocity="1.0"/>
  </joint>

  <joint name="thigh_right_to_lower_leg_right" type="revolute">
    <parent link="thigh_right"/>
    <child link="lower_leg_right"/>
    <origin xyz="0 -0.2 0" rpy="0 0 0"/>
    <axis xyz="0 1 0"/>
    <limit lower="-1.57" upper="0" effort="100.0" velocity="1.0"/>
  </joint>

  <!-- Chair -->
  <link name="chair">
    <visual>
      <geometry>
        <box size="0.5 0.5 0.05"/>
      </geometry>
      <material name="Brown">
        <color rgba="0.545 0.271 0.075 1"/>
      </material>
    </visual>
  </link>

  <joint name="chair_to_torso" type="fixed">
    <parent link="chair"/>
    <child link="torso"/>
    <origin xyz="0 0 0.25" rpy="0 0 0"/>
  </joint>

</robot>
